<?xml version='1.0'?>
<sdf version='1.4'>
    <model name="my_robot">
        <static>false</static>
        <self_collide>1</self_collide>
        <link name='chassis'>
            <pose>0 0 .05 0 0 0</pose>
            <inertial>
                <mass>50</mass>
            </inertial>
            <collision name='collision'>
                <geometry>
                    <cylinder>
                        <radius>.5</radius>
                        <length>.1</length>
                    </cylinder>
                </geometry>
            </collision>

            <visual name='visual'>
                <geometry>
                    <cylinder>
                        <radius>.5</radius>
                        <length>.1</length>
                    </cylinder>
                </geometry>
            </visual>
        </link>
        <link name='arm1'>
            <pose>0 0 .125 0 0 0</pose>

            <collision name='collision'>
                <geometry>
                    <cylinder>
                        <radius>.1</radius>
                        <length>.05</length>
                    </cylinder>
                </geometry>
            </collision>

            <visual name='visual'>
                <geometry>
                    <cylinder>
                        <radius>.1</radius>
                        <length>.05</length>
                    </cylinder>
                </geometry>
            </visual>
        </link>
        <link name='arm2'>
            <pose>0 0 1.15 0 0 0</pose>

            <collision name='collision'>
                <geometry>
                    <cylinder>
                        <radius>.05</radius>
                        <length>2.0</length>
                    </cylinder>
                </geometry>
            </collision>

            <visual name='visual'>
                <geometry>
                    <cylinder>
                        <radius>.05</radius>
                        <length>2.0</length>
                    </cylinder>
                </geometry>
            </visual>
        </link>
        <link name='arm3'>  
            <pose>0 0 2.65 0 0 0</pose>
            <gravity>0</gravity>
            <collision name='collision'>
                <geometry>
                    <cylinder>
                        <radius>.05</radius>
                        <length>1</length>
                    </cylinder>
                </geometry>
            </collision>

            <visual name='visual'>
                <geometry>
                    <cylinder>
                        <radius>.05</radius>
                        <length>1</length>
                    </cylinder>
                </geometry>
            </visual>
        </link>
        <link name='arm4'>
            <pose>0 0 3.4 0 0 0</pose>
            <gravity>0</gravity>
            <collision name='collision'>
                <geometry>
                    <cylinder>
                        <radius>.05</radius>
                        <length>.5</length>
                    </cylinder>
                </geometry>
            </collision>

            <visual name='visual'>
                <geometry>
                    <cylinder>
                        <radius>.05</radius>
                        <length>.5</length>
                    </cylinder>
                </geometry>
            </visual>
        </link>
        <link name='arm5'>
            <pose>0 0 3.675 0 0 0</pose>

            <collision name='collision'>
                <geometry>
                    <cylinder>
                        <radius>.05</radius>
                        <length>0.05</length>
                    </cylinder>
                </geometry>
            </collision>

            <visual name='visual'>
                <geometry>
                    <cylinder>
                        <radius>.05</radius>
                        <length>0.05</length>
                    </cylinder>
                </geometry>
            </visual>
        </link>



        <link name="palm">
            <pose>0.0 0.0 3.75 0 0 0</pose>
            <inertial>
                <inertia>
                    <ixx>0.01</ixx>
                    <ixy>0</ixy>
                    <ixz>0</ixz>
                    <iyy>0.01</iyy>
                    <iyz>0</iyz>
                    <izz>0.01</izz>
                </inertia>
                <mass>0.5</mass>
            </inertial>
            <collision name="collision">
                <geometry>
                    <box>
                        <size>0.1 0.2 0.1</size>
                    </box>
                </geometry>
            </collision>
            <visual name="visual">
                <geometry>
                    <box>
                        <size>0.1 0.2 0.1</size>
                    </box>
                </geometry>
                <material>
                    <script>Gazebo/Red</script>
                </material>
            </visual>
        </link>
        <link name="left_finger">
            <pose>0.1 0.2 3.75 0 0 -0.78539</pose>
            <gravity>0</gravity>
            <inertial>
                <inertia>
                    <ixx>0.01</ixx>
                    <ixy>0</ixy>
                    <ixz>0</ixz>
                    <iyy>0.01</iyy>
                    <iyz>0</iyz>
                    <izz>0.01</izz>
                </inertia>
                <mass>0.01</mass>
            </inertial>
            <collision name="collision">
                <geometry>
                    <box>
                        <size>0.1 0.3 0.1</size>
                    </box>
                </geometry>
            </collision>
            <visual name="visual">
                <geometry>
                    <box>
                        <size>0.1 0.5 0.1</size>
                    </box>
                </geometry>
                <material>
                    <script>Gazebo/Blue</script>
                </material>
            </visual>
        </link>
        <link name="right_finger">
            <pose>0.1 -0.2 3.75 0 0 .78539</pose>
            <gravity>0</gravity>
            <inertial>
                <inertia>
                    <ixx>0.01</ixx>
                    <ixy>0</ixy>
                    <ixz>0</ixz>
                    <iyy>0.01</iyy>
                    <iyz>0</iyz>
                    <izz>0.01</izz>
                </inertia>
                <mass>0.01</mass>
            </inertial>
            <collision name="collision">
                <geometry>
                    <box>
                        <size>0.1 0.5 0.1</size>
                    </box>
                </geometry>
            </collision>
            <visual name="visual">
                <geometry>
                    <box>
                        <size>0.1 0.5 0.1</size>
                    </box>
                </geometry>
                <material>
                    <script>Gazebo/Green</script>
                </material>
            </visual>
        </link>


        <model name="box">
            <static>false</static>
            <link name="box">
                <inertial>
                    <mass>0.05</mass>
                    <inertia> <!-- inertias are tricky to compute -->
                    <!-- http://gazebosim.org/tutorials?tut=inertia&cat=build_robot -->
                    <ixx>0.00107568</ixx>       <!-- for a box: ixx = 0.083 * mass * (y*y + z*z) 0.0648 -->
                    <ixy>0.0</ixy>         <!-- for a box: ixy = 0 -->
                    <ixz>0.0</ixz>         <!-- for a box: ixz = 0 -->
                    <iyy>0.00107568</iyy>       <!-- for a box: iyy = 0.083 * mass * (x*x + z*z) -->
                    <iyz>0.0</iyz>         <!-- for a box: iyz = 0 -->
                    <izz>0.00107568</izz>       <!-- for a box: izz = 0.083 * mass * (x*x + y*y) -->
                    </inertia>
                </inertial>

                <pose>1.0 2.15 0.1 0 0 0</pose>

                <collision name="collision">
                    <geometry>
                    <box>
                        <size>0.2 0.2 0.2</size>
                    </box>
                    </geometry>
                    <surface>
                        <friction>
                            <ode>
                                <mu>1000.0</mu>
                                <mu2>1000.0</mu2>
                                <kp>1000000.0</kp>
                                <kd>100000.0</kd>
                                <slip1>0</slip1>
                                <slip2>0</slip2>
                                <minDepth>0.001</minDepth>
                                <maxVel>0</maxVel>
                            </ode>
                            <torsional>
                                <coefficient>1000.0</coefficient>
                                <patch_radius>0.1</patch_radius>
                                <slip>0</slip>
                            </torsional>
                        </friction>
                    </surface>
                </collision>
                <visual name="visual">
                    <geometry>
                    <box>
                        <size>0.2 0.2 0.2</size>
                    </box>
                    </geometry>
                </visual>
            </link>
        </model>

        <joint type="revolute" name="chasis_arm1_joint">
            <pose>0 0 -0.025 0 0 0</pose>
            <child>arm1</child>
            <parent>chassis</parent>
            <axis>
                <xyz>0 0 1</xyz>
            </axis>
        </joint>
         <joint type="revolute" name="arm1_arm2_joint">
            <pose>0 0 -1 0 0 0</pose>
            <child>arm2</child>
            <parent>arm1</parent>
            <axis>
                <xyz>1 0 0</xyz>
            </axis>
        </joint>
        <joint name="arm2_arm3_joint" type="revolute">
            <parent>arm2</parent>
            <child>arm3</child>
            <pose>0 0 -0.5 0 0 0</pose>
            <axis>
                <xyz>1 0 0</xyz>
                <dynamics>
                    <damping>1.0</damping>
                    <limit>
                        <lower>1.0</lower>
                        <upper>1.0</upper>
                        <effort>40</effort>
                        <velocity>1.0</velocity>
                    </limit>
                </dynamics>
            </axis>
        </joint>

        <joint name="arm3_arm4_joint" type="revolute">
            <parent>arm3</parent>
            <child>arm4</child>
            <pose>0 0 -0.25 0 0 0</pose>
            <axis>
                <xyz>1 0 0</xyz>
                <dynamics>
                    <damping>1.0</damping>
                    <limit>
                        <lower>1.0</lower>
                        <upper>1.0</upper>
                        <effort>40</effort>
                        <velocity>1.0</velocity>
                    </limit>
                </dynamics>
            </axis>
        </joint>
        <joint type="revolute" name="arm4_arm5_joint">
            <pose>0 0 -0.025 0 0 0</pose>
            <child>arm5</child>
            <parent>arm4</parent>
            <axis>
            <dynamics>
                    <damping>1.0</damping>
                    <limit>
                        <lower>1.0</lower>
                        <upper>1.0</upper>
                        <effort>40</effort>
                        <velocity>1.0</velocity>
                    </limit>
                </dynamics>
                <xyz>0 1 0</xyz>
            </axis>
        </joint>

        
        <joint name="palm_riser" type="revolute">
            <pose>0 0 -0.05 0 0 0</pose>
            <child>palm</child>
            <parent>arm5</parent>
            <axis>
            <dynamics>
                    <damping>1.0</damping>
                    <limit>
                        <lower>1.0</lower>
                        <upper>1.0</upper>
                        <effort>40</effort>
                        <velocity>1.0</velocity>
                    </limit>
                </dynamics>
                <xyz>0 0 1</xyz>
            </axis>
        </joint>


        <!-- new jointed -->
        <joint name="palm_left_finger" type="revolute">
            <pose>0 -0.15 0 0 0 0</pose>
            <child>left_finger</child>
            <parent>palm</parent>
            <axis>
                <dynamics>
                    <damping>1.0</damping>
                    <friction>.3</friction>
                    <limit>
                        <lower>1.0</lower>
                        <upper>1.0</upper>
                        <effort>40</effort>
                        <velocity>1.0</velocity>
                    </limit>
                </dynamics>
                <xyz>0 0 1</xyz>
            </axis>
        </joint>
       
        <joint name="palm_right_finger" type="revolute">
            <pose>0 0.15 0 0 0 0</pose>
            <child>right_finger</child>
            <parent>palm</parent>
            <axis>
                <dynamics>
                    <damping>1.0</damping>
                    <friction>.3</friction>
                    <limit>
                        <lower>1.0</lower>
                        <upper>1.0</upper>
                        <effort>40</effort>
                        <velocity>1.0</velocity>
                    </limit>
                </dynamics>
                <xyz>0 0 1</xyz>
            </axis>
        </joint>
        <plugin name="arm_control" filename="libarm_gazebo.so" />
        <plugin name="grip_control" filename="libGRIPPER.so" />
        <plugin name="ik_control" filename="libINVERSE_K.so" />

    </model>
</sdf>